Workbook

Sheet 6061-T6 Tank Specs
B2: Store Bought T6-6061 Alumimum Tube
B3: This Portion calculates the Factor of Saftey for a commercially available Aluminum tube as the basis for the TEZ fuel tanks
B4: Outer Diameter (d_o) [in] | C4: Thickness (t) [in] | D4: Yield Strength (Sigma_y) [psi] | E4: Allowable Stress (S) [psi] (ASME) | F4: Radius (r) [in] | G4: Mean Radius (r_m) [in] | H4: Internal Operating Pressure (P) [psi]
B5: 4 | C5: 0.1875 | D5: 40000 | E5: =D5/1.5 -> 26666.667 | F5: =B5/2 -> 2 | G5: =(B5-0.5*C5)/2 -> 1.953125 | H5: 360
B7: Hoop Stress (Sigma_h) [psi] | C7: Axial Stress (Tau_a) [psi] | D7: Burst Pressure | E7: Burst Hoop Stress (Sigma_h) [psi] | F7: Burst Axial Stress (Tau_a) [psi] | G7: Desired Bulkhead FOS | H7: Bulkhead stress [psi]
B8: =(H5*G5)/C5 -> 3750 | C8: =B8/2 -> 1875 | D8: =(2*E5*C5)/B5 -> 2500 | E8: =(D8*G5)/C5 -> 26041.667 | F8: =E8/2 -> 13020.833 | G8: 4 | H8: =(3*H5*((H19/2)^2))/(4*(H12^2)) -> 10000
B11: At MEOP --> | C11: FOS (ASME) | D11: FOS (ASME) (Corrected) | E11: At burst pressure (2.78x MEOP) --> | F11: FOS (ASME) | G11: FOS (ASME Corrected) | H11: Min. Bulkhead Thickness [in] | J11: Note: Old ASME specifications typically defunct, use Corrected values
C12: =E5/B8 -> 7.1111111 | D12: =C12*1.5 -> 10.666667 | F12: =E5/E8 -> 1.024 | G12: =F12*1.5 -> 1.536 | H12: =SQRT((G8*3*H5*((H19/2)^2))/(4*D5)) -> 0.30911872
B15: Links
B16: Tube | C16: here
B17: Material Sheet: | C17: here
B18: MMPDS Sheet: | C18: here
F19: Bore Diameter (d9) [in] | H19: =('O-Ring (2-340) Parameters'!F12)-0.0017 -> 3.7624732

Sheet O-Ring (2-340) Parameters
B4: O-ring OD [in] | C4: O-ring ID (d1) [in] | D4: Backup O-ring Area | E4: O-ring Width [in] | F4: O-ring Area [in^2] | G4: Number of Backup Rings
B5: 3.77 | C5: =C12 -> 3.35 | D5: 0.01281 | E5: =D12 -> 0.20984252 | F5: =PI()*(D12^2)/4 -> 0.034584131 | G5: 0
A7: Calculating parameters --> | B7: Groove Diameter [in] | C7: Chamber Width (to tank wall) [in] | D7: Gland Width (b) [in] | E7: Gland Area [in^2] | F7: Squeeze (%) | G7: Stretch (%) | H7: Gland Fill (%)
B8: =H12 -> 3.45 | C8: =(F12/2)-(H12/2) -> 0.15708661 | D8: =E12 -> 0.28346457 | E8: =C8*D8 -> 0.044528489 | F8: =((E5-C8)/E5)*100 -> 25.140713 | G8: =((B8-C5)/C5)*100 -> 2.9850746 | H8: =(((D5*G5)+F5)/E8)*100 -> 77.667425
A10: From Paker handbook: | B10: Dash Number | C10: ID (d1) | D10: O-ring Width (d2) | E10: Groove Width (0 BURs) (b1) | F10: Bore Diameter (d4/d9) | H10: Groove Diameter (d3)
A11: (metric) --> | B11: 2-340 | C11: 85.09 | D11: 5.33 | E11: 7.2 | F11: 95.61 | H11: 87.63
A12: (imperial) --> | C12: =C11/25.4 -> 3.35 | D12: =D11/25.4 -> 0.20984252 | E12: =E11/25.4 -> 0.28346457 | F12: =F11/25.4 -> 3.7641732 | H12: =H11/25.4 -> 3.45
B13: Tolerances: (in) | D13: MAX (+) | E13: 0.0098 | F13: 0.0025 | G13: -0.0017 | H13: 0
D14: MIN (-) | E14: 0 | F14: 0 | G14: -0.0033 | H14: -0.0039
B15: Tolerances found here | E15: ISO tolerances: | F15: H8 | G15: f7 | H15: h9
B16: (direct from handbook) -->
B18: Links: | C18: 431 O-rings | McMaster-Carr #9452K418 link
A22: Spacing Notes | B22: Space between o-rings should be 1-1.5x the diameter of the o-rings and no less than 1 mm
B23: Lip width (distance from end of bulkhead to first o-ring) should be equal or greater than the groove width

Sheet O-Ring (2-236) Parameters
B4: O-ring OD [in] | C4: O-ring ID (d1) [in] | D4: Backup O-ring Area | E4: O-ring Width [in] | F4: O-ring Area [in^2] | G4: Number of Backup Rings
B5: 3.512 | C5: =C12 -> 3.2338583 | D5: 0.005831 | E5: =D12 -> 0.13897638 | F5: =PI()*(D12^2)/4 -> 0.015169521 | G5: 1
A7: Calculating parameters --> | B7: Groove Diameter [in] | C7: Chamber Width (to tank wall) [in] | D7: Gland Width (b) [in] | E7: Gland Area [in^2] | F7: Squeeze (%) | G7: Stretch (%) | H7: Gland Fill (%)
B8: =H12 -> 3.3307087 | C8: =ABS((F12/2)-(H12/2)) -> 0.10255906 | D8: =E12 -> 0.2519685 | E8: =C8*D8 -> 0.025841652 | F8: =((E5-C8)/E5)*100 -> 26.203966 | G8: =((B8-C5)/C5)*100 -> 2.9948868 | H8: =(((D5*G5)+F5)/E8)*100 -> 81.26617 | I8: <<
A10: From Paker handbook: | B10: Dash Number | C10: ID (d1) | D10: O-ring Width (d2) | E10: Groove Width (0 BURs) (b1) | F10: Bore Diameter (d4/d9) | H10: Groove Diameter (d3)
A11: (metric) --> | B11: 2-236 | C11: 82.14 | D11: 3.53 | E11: 6.4 | F11: 89.81 | H11: 84.6
A12: (imperial) --> | C12: =C11/25.4 -> 3.2338583 | D12: =D11/25.4 -> 0.13897638 | E12: =E11/25.4 -> 0.2519685 | F12: =F11/25.4 -> 3.5358268 | H12: =H11/25.4 -> 3.3307087
B13: Tolerances: (in) | D13: MAX (+) | E13: 0.0098 | F13: 0.0025 | G13: -0.0017 | H13: 0
D14: MIN (-) | E14: 0 | F14: 0 | G14: -0.0033 | H14: -0.0039
B15: Tolerances found here | E15: ISO tolerances: | F15: H8 | G15: f7 | H15: h9
B16: (direct from handbook) -->
B18: Links: | C18: 431 O-rings | McMaster-Carr #9452K418 link
A22: Spacing Notes | B22: Space between o-rings should be 1-1.5x the diameter of the o-rings and no less than 1 mm
B23: Lip width (distance from end of bulkhead to first o-ring) should be equal or greater than the groove width

Sheet O-Ring (2-253) Parameters
B4: O-ring OD [in] | C4: O-ring ID (d1) [in] | D4: Backup O-ring Area | E4: O-ring Width [in] | F4: O-ring Area [in^2] | G4: Number of Backup Rings | M4: O-ring OD | N4: O-ring ID | O4: Width of o-ring | P4: Area of o-ring | Q4: Backup O-ring Area
B5: 5.637 | C5: =C12 -> 5.3590551 | D5: 0 | E5: =D12 -> 0.13897638 | F5: =PI()*(D12^2)/4 -> 0.015169521 | G5: 0 | M5: 6.02 | N5: 5.6 | O5: =M5-N5 -> 0.42 | P5: =PI()*((O5^2)/4) -> 0.13854424 | Q5: =0.076*(6.019-5.653) -> 0.027816
A7: Calculating parameters --> | B7: Groove Diameter [in] | C7: Chamber Width (to tank wall) [in] | D7: Gland Width (b) [in] | E7: Gland Area [in^2] | F7: Squeeze (%) | G7: Stretch (%) | H7: Gland Fill (%) | M7: Width of Chamber (Groove diameter to wall) | N7: Groove Diameter | O7: Gland Area | P7: Gland Width | Q7: <-- must be greater than
B8: =H12 -> 5.511811 | C8: =(F12/2)-(H12/2) -> 0.1003937 | D8: =E12 -> 0.19685039 | E8: =C8*D8 -> 0.01976254 | F8: =((E5-C8)/E5)*100 -> 27.76204 | G8: =((B8-C5)/C5)*100 -> 2.8504261 | H8: =(((D5*G5)+F5)/E8)*100 -> 76.758965 | M8: =O5-(0.1*O5) -> 0.378 | N8: =(0.05*N5)+N5 -> 5.88 | O8: =(P5+(2*Q5))/0.85 -> 0.22844263 | P8: =O8/M8 -> 0.60434558 | Q8: =(0.076*2)+O5 -> 0.572
A10: From Paker handbook: | B10: Dash Number | C10: ID (d1) | D10: O-ring Width (d2) | E10: Groove Width (0 BURs) (b1) | F10: Bore Diameter (d4/d9) | H10: Groove Diameter (d3)
A11: (metric) --> | B11: 2-253 | C11: 136.12 | D11: 3.53 | E11: 5 | F11: 145.1 | H11: 140
A12: (imperial) --> | C12: =C11/25.4 -> 5.3590551 | D12: =D11/25.4 -> 0.13897638 | E12: =E11/25.4 -> 0.19685039 | F12: =F11/25.4 -> 5.7125984 | H12: =H11/25.4 -> 5.511811
B13: Tolerances: (in) | D13: MAX (+) | E13: 0.0098 | F13: 0.0025 | G13: -0.0017 | H13: 0
D14: MIN (-) | E14: 0 | F14: 0 | G14: -0.0033 | H14: -0.0039
B15: Tolerances found here | E15: ISO tolerances: | F15: H8 | G15: f7 | H15: h9
B16: (direct from handbook) -->
B18: Links: | C18: 358 O-rings | McMaster-Carr #9452K514 link
A22: Spacing Notes | B22: Space between o-rings should be 1-1.5x the diameter of the o-rings and no less than 1 mm
B23: Lip width (distance from end of bulkhead to first o-ring) should be equal or greater than the groove width

Sheet Bolt Circle Calculations
B2: Bulkhead Mounting Screw Calculations
B4: Inner casing diameter [in] | C4: Thickness [in] | D4: Operating pressure [psi] | E4: Number of bolts | F4: Bearing Yield Strength [psi] | G4: Shear Strength [psi] | H4: Ultimate Tensile Strength [psi] | I4: Yield Tensile Strength [psi]
B5: ='6061-T6 Tank Specs'!B5-2*C5 -> 3.625 | C5: ='6061-T6 Tank Specs'!C5 -> 0.1875 | D5: ='6061-T6 Tank Specs'!H5 -> 360 | E5: 8 | F5: 56000 | G5: 30000 | H5: 45000 | I5: 40000
B7: Bolt Force | C7: Tear-out FOS | D7: Tear-out Stress [psi] | E7: Distance from end to bolt edge (Emin) [in] | F7: Bolt TPI (UNF)
B8: =((PI()/4)*(B5^2)*D5)/E5 -> 464.42802 | C8: 4 | D8: =G5/C8 -> 7500 | E8: =B8/(2*C5*D8) -> 0.16512996 | F8: 16
B10: Bearing FOS | C10: Bearing Stress [psi] | D10: Major bolt diameter [in] | E10: Minor bolt diameter [in] | F10: Tensile stress [psi] | G10: Tensile FOS | H10: Bolt shear stress [psi] | I10: Bolt shear FOS
B11: 4 | C11: =F5/B11 -> 14000 | D11: =B8/(C5*C11) -> 0.17692496 | E11: =D11-(1.3/F8) -> 0.095674961 | F11: =((PI()/4)*D5*(B5^2))/(C5*(((B5+C5)*PI())-(E5*D11))) -> 1876.1353 | G11: =I5/F11 -> 21.320424 | H11: =((B5^2)*D5)/((E11^2)*E5) -> 64599.915 | I11: =(H5*0.75)/H11 -> 0.52244651
A13: Governing Force --> | B13: Bolt shear FOS | C13: Bolt shear stress [psi] | D13: Major bolt diameter [in] | E13: Minor bolt diameter [in] | F13: Bearing Stress [psi] | G13: Bearing FOS | H13: Tensile stress [psi] | I13: Tensile FOS
B14: 4 | C14: =(H5*0.75)/B14 -> 8437.5 | D14: =E14+(1.3/F8) -> 0.34598257 | E14: =SQRT(((B5^2)*D5)/(C14*E5)) -> 0.26473257 | F14: =B8/(D14*C5) -> 7159.1741 | G14: =F5/F14 -> 7.8221313 | H14: =((PI()/4)*D5*(B5^2))/(C5*((B5+C5)*PI()-(E5*D14))) -> 2151.6563 | I14: =I5/H14 -> 18.59033
B16: Tensile FOS | C16: Tensile stress [psi] | D16: Major bolt diameter [in] | E16: Minor bolt diameter [in] | F16: Bolt shear stress [psi] | G16: Bolt shear FOS | H16: Bearing Stress [psi] | I16: Bearing FOS
B17: 6.5 | C17: =I5/B17 -> 6153.8462 | D17: =((PI()*(B5+C5))-(((B5^2)*D5*PI())/(4*C5*C17)))/E5 -> 1.094661 | E17: =D17-(1.3/F8) -> 1.013411 | F17: =((B5^2)*D5)/((E17^2)*E5) -> 575.78101 | G17: =(H5*0.75)/F17 -> 58.616035 | H17: =B8/(D17*C5) -> 2262.7549 | I17: =F5/H17 -> 24.748593
B19: Major bolt diameter [in] | C19: Minor bolt diameter [in] | D19: Tensile stress [psi] | E19: Tensile FOS | F19: Bolt shear stress [psi] | G19: Bolt shear FOS | H19: Bearing Stress [psi] | I19: Bearing FOS
B20: 0.375 | C20: =B20-(1.3/F8) -> 0.29375 | D20: =((PI()/4)*D5*(B5^2))/(C5*((B5+C5)*PI()-(E5*B20))) -> 2207.2947 | E20: =I5/D20 -> 18.12173 | F20: =((B5^2)*D5)/((C20^2)*E5) -> 6852.8746 | G20: =(H5*0.75)/F20 -> 4.9249405 | H20: =B8/(B20*C5) -> 6605.1986 | I20: =F5/H20 -> 8.4781706
B23: Button Head Hex-Drive Screws: 1/2"-20 size | 1" length | E23: P-List (McMaster)
B24: Stainless Steel Button Head Hex-Drive Screws | E24: link

Sheet Final Calculations
B2: Final Calculations | K2: Associated Equations | N2: =PI()*N3^2 -> 12.566371 | O2: =PI()*O3^2 -> 11.044662
B3: Geometric Parameters | N3: ='Final Calculations'!B5/2 -> 2 | O3: ='Final Calculations'!G5/2 -> 1.875
B4: Outer Diameter (d_o) [in] | C4: Cylinder Thickness (t_c) [in] | D4: Mean Cyl Radius (t_mc) | E4: Dome Thickness (t_d) [in] | F4: Mean Diameter (r_m) [in] | G4: Inner Diameter (d_i) [in] | H4: Semi-Major Axis (a) [in] | I4: Semi-Minor Axis (b) [in]
B5: ='6061-T6 Tank Specs'!B5 -> 4 | C5: ='6061-T6 Tank Specs'!C5 -> 0.1875 | D5: =(B5-C5)/2 -> 1.90625 | E5: 0.125 | F5: =B5-(2*E5)/2 -> 3.875 | G5: =B5-2*E5 -> 3.75 | H5: =F5/2 -> 1.9375 | I5: =F5/4 -> 0.96875 | N5: E | O5: I | P5: =(PI()^2*10000000*O6)/(31.25^2) -> 288959.12
B6: Given Parameters | N6: =10000*1000 -> 10000000 | O6: =PI()/4*(N3^4-O3^4) -> 2.8591484
B7: Internal Pressure (P) [psi] | C7: Yield Strength (Sigma_y) [psi] | D7: Shear Strength (Tau_y) [psi] | E7: Weld Efficiency (E) | F7: Shape Factor (K)
B8: ='6061-T6 Tank Specs'!H5 -> 360 | C8: ='6061-T6 Tank Specs'!D5 -> 40000 | D8: 0 | E8: 0 | F8: =1/6*(2+((G5)/(2*G5/4))^2) -> 1
B10: Cylindrical Wall Calculations | M10: 40000 | N10: =4000/(N2-O2) -> 2628.6236 | O10: =M10/N10 -> 15.217089
B11: Hoop Stress (Sigma_h) [psi] | C11: Axial Stress (Tau_a) [psi]
B12: =B8*D5/C5 -> 3660 | C12: =B12/2 -> 1830
B14: FOS | C14: FOS
B15: =C8/B12 -> 10.928962 | C15: =C8/C12 -> 21.857923
B17: Eliptical Dome - Crown
B18: R of Curvature (r_1c) [in] | C18: R of Somthing (r_2c) [in] | D18: Meridional Stress (Sig_1c) [psi] | E18: Hoop Stress (Sig_2c) [psi] | F18: Max Shear (Tau_c) [psi]
B19: =H5^2/I5 -> 3.875 | C19: =H5^2/I5 -> 3.875 | D19: =(B8*H5^2)/(2*I5*E5) -> 5580 | E19: =(B8*H5^2)/(2*I5*E5) -> 5580 | F19: =B8/4*((H5^2)/(I5*E5)+1) -> 2880
D21: FOS | E21: FOS | F21: FOS
D22: =C8/D19 -> 7.1684588 | E22: =C8/E19 -> 7.1684588 | F22: =D8/F19 -> 0
B24: Eliptical Dome - Equator
B25: R of Curvature (r_1e) [in] | C25: R of Somthing (r_2e) [in] | D25: Meridional Stress (Sig_1e) [psi] | E25: Hoop Stress (Sig_2e) [psi] | F25: Max Shear (Tau_e) [psi]
B26: =I5^2/H5 -> 0.484375 | C26: =H5 -> 1.9375 | D26: =(B8*H5)/(2*E5) -> 2790 | E26: =(B8*H5)/E5*(1-(H5^2)/(2*I5^2)) -> -5580 | F26: =(B8*H5)/(4*E5)*((H5^2)/(I5)^2+1) -> 6975
D28: FOS | E28: FOS | F28: FOS
D29: =C8/D26 -> 14.336918 | E29: =ABS(C8/E26) -> 7.1684588 | F29: =D8/F26 -> 0
B32: ASME Claculator Inputs for Eliptical Tank Domes- For Fun/Double Check
B33: Internal Pressure (P) [psi] | C33: Outer Diameter (d_o) [in] | D33: Decided Thickness (t) [in] | E33: Allowable Stress (S) [psi] | F33: Weld Efficiency (E) | G33: Inner Hight (h) [in]
B34: =B8 -> 360 | C34: =B5 -> 4 | D34: =E5 -> 0.125 | E34: =C8/1.5 -> 26666.667 | F34: =E8 -> 0 | G34: =(C34-2*D34)/4 -> 0.9375
B35: Internal Pressure (P) (N/mm^2) | C35: Outer Diameter (d_o) (mm) | D35: Decided Thickness (t) (mm) | E35: Allowable Stress (S) (N/mm^2) | F35: Weld Efficiency (E) | G35: Inner Hight (h) (mm)
B36: =B34*0.00689476 -> 2.4821136 | C36: =C34*25.4 -> 101.6 | D36: =D34*25.4 -> 3.175 | E36: =E34*0.00689476 -> 183.86027 | F36: =F34 -> 0 | G36: =G34*25.4 -> 23.8125
B38: Inner Diameter (d_i) (mm) | C38: diameter/height ratio (d_i/2h) | D38: Shape Factor (K) | E38: Shape Factor 1 (K1)
B39: =C36-(2*D36) -> 95.25 | C39: =B39/(2*G36) -> 2 | D39: =1/6*(2+(C39)^2) -> 1 | E39: =D39-0.09 -> 0.91
B41: Required Thickness (t_req1) (mm) | C41: Required Thickness (t_req2) (mm)
B42: =(B36*C36*D39)/(2*E36*F36+2*B36*(D39-0.1)) -> 56.444444 | C42: =(B36*B39*D39)/(2*E36*F36-0.2*B36) -> -476.25
B43: Required Thickness (t_req1) [in] | C43: Required Thickness (t_req2) [in]
B44: =B42/25.4 -> 2.2222222 | C44: =C42/25.4 -> -18.75
B46: FOS | C46: FOS
B47: =D34/B44 -> 0.05625 | C47: =D34/C44 -> -0.0066666667
B50: ASME Claculator Inputs for Cylindrical Pressure Vessel - For Fun/Double Check
B51: Internal Pressure (P) [psi] | C51: Outer Diameter (d_o) [in] | D51: Decided Thickness (t) [in] | E51: Allowable Stress (S) [psi] | F51: Weld Efficiency (E) | G51: Inner Hight (h) [in]
B52: =B34 -> 360 | C52: =C34 -> 4 | D52: =C5 -> 0.1875 | E52: =E34 -> 26666.667 | F52: =F34 -> 0 | G52: =G34 -> 0.9375
B53: Internal Pressure (P) (N/mm^2) | C53: Outer Diameter (d_o) (mm) | D53: Decided Thickness (t) (mm) | E53: Allowable Stress (S) (N/mm^2) | F53: Weld Efficiency (E) | G53: Inner Hight (h) (mm)
B54: =B52*0.00689476 -> 2.4821136 | C54: =C52*25.4 -> 101.6 | D54: =D52*25.4 -> 4.7625 | E54: =E52*0.00689476 -> 183.86027 | F54: =F52 -> 0 | G54: =G52*25.4 -> 23.8125
...
